<?xml version="1.0" ?>
<!-- =================================================================================== -->
<!-- |    This document was autogenerated by xacro from urdf/athena.urdf.xacro         | -->
<!-- |    EDITING THIS FILE BY HAND IS NOT RECOMMENDED                                 | -->
<!-- =================================================================================== -->
<robot name="athena">
  <include filename="/home/arcturus/AllSeaingVehicle/src/sim_suite/urdf/inertia.xacro"/>
  <link name="dummy_base_link"/>
  <joint name="dummy_base_joint" type="fixed">
    <parent link="dummy_base_link"/>
    <child link="base_link"/>
    <origin rpy="0 0 0" xyz="0 0 0"/>
  </joint>
  <link name="base_link">
    <visual>
      <geometry>
        <box size="1.0 0.5 0.05"/>
      </geometry>
      <material name="brown">
        <color rgba="0.5 0.5 0 1"/>
      </material>
    </visual>
    <collision>
      <geometry>
        <box size="1.0 0.5 0.05"/>
      </geometry>
    </collision>
    <inertial>
      <mass value=".10"/>
      <inertia ixx="0.008354166666666668" ixy="0" ixz="0" iyy="0.010416666666666666" iyz="0" izz="0.002104166666666667"/>
    </inertial>
  </link>
  <link name="right_hull">
    <visual>
      <geometry>
        <cylinder length="1.0" radius="0.1"/>
      </geometry>
      <material name="yellow">
        <color rgba="1 1 0 1"/>
      </material>
    </visual>
    <collision>
      <geometry>
        <cylinder length="1.0" radius="0.1"/>
      </geometry>
    </collision>
    <intertial>
      <mass value=".5"/>
      <inertia ixx="0.042916666666666665" ixy="0" ixz="0" iyy="0.042916666666666665" iyz="0" izz="0.0025000000000000005"/>
    </intertial>
  </link>
  <joint name="right_hull_joint" type="fixed">
    <parent link="base_link"/>
    <child link="right_hull"/>
    <origin rpy="0 1.57 0" xyz="0 0.25 -0.125"/>
  </joint>
  <link name="left_hull">
    <visual>
      <geometry>
        <cylinder length="1.0" radius="0.1"/>
      </geometry>
      <material name="yellow">
        <color rgba="1 1 0 1"/>
      </material>
    </visual>
    <collision>
      <geometry>
        <cylinder length="1.0" radius="0.1"/>
      </geometry>
    </collision>
    <intertial>
      <mass value=".5"/>
      <inertia ixx="0.042916666666666665" ixy="0" ixz="0" iyy="0.042916666666666665" iyz="0" izz="0.0025000000000000005"/>
    </intertial>
  </link>
  <joint name="left_hull_joint" type="fixed">
    <parent link="base_link"/>
    <child link="left_hull"/>
    <origin rpy="0 1.57 0" xyz="0 -0.25 -0.125"/>
  </joint>
  <link name="camera_stand">
    <visual>
      <geometry>
        <box size=".025 .025 0.1"/>
      </geometry>
      <material name="red">
        <color rgba="1 0 0 1"/>
      </material>
    </visual>
    <inertial>
      <mass value=".05"/>
      <inertia ixx="4.427083333333334e-05" ixy="0" ixz="0" iyy="5.208333333333335e-06" iyz="0" izz="4.427083333333334e-05"/>
    </inertial>
  </link>
  <joint name="camera_stand_joint" type="fixed">
    <parent link="base_link"/>
    <child link="camera_stand"/>
    <origin xyz="0.35 0 0.05"/>
  </joint>
  <link name="camera_link">
    <visual>
      <geometry>
        <box size=".025 .05 .025"/>
      </geometry>
      <material name="black">
        <color rgba="0 0 0 1"/>
      </material>
    </visual>
    <inertial>
      <mass value=".05"/>
      <inertia ixx="5.208333333333335e-06" ixy="0" ixz="0" iyy="1.3020833333333336e-05" iyz="0" izz="1.3020833333333336e-05"/>
    </inertial>
  </link>
  <gazebo reference="camera_link">
    <sensor name="camera1" type="camera">
      <horizontal_fov>1.047</horizontal_fov>
      <visualize>true</visualize>
      <image>
        <width>640</width>
        <height>480</height>
      </image>
      <clip>
        <near>0.1</near>
        <far>100</far>
      </clip>
      <always_on>1</always_on>
      <update_rate>30</update_rate>
      <plugin filename="libgazebo_ros_camera.so" name="camera_controller">
        <alwaysOn>1</alwaysOn>
        <updateRate>0.0</updateRate>
        <cameraName>zed2i</cameraName>
        <imageTopicName>/zed2i/zed_node/rgb/image_rect_color</imageTopicName>
        <cameraInfoTopicName>/zed_node/camera_info</cameraInfoTopicName>
        <frameName>camera_link</frameName>
        <hackBaseline>0.07</hackBaseline>
        <distortionK1>0.0</distortionK1>
        <distortionK2>0.0</distortionK2>
        <distortionK3>0.0</distortionK3>
        <distortionT1>0.0</distortionT1>
        <distortionT2>0.0</distortionT2>
      </plugin>
    </sensor>
  </gazebo>
  <joint name="camera_joint" type="fixed">
    <parent link="camera_stand"/>
    <child link="camera_link"/>
    <origin xyz="0 0 0.05"/>
  </joint>
  <link name="lidar_stand">
    <visual>
      <geometry>
        <box size=".025 .025 0.3"/>
      </geometry>
      <material name="red">
        <color rgba="1 0 0 1"/>
      </material>
    </visual>
    <inertial>
      <mass value=".25"/>
      <inertia ixx="0.0018880208333333333" ixy="0" ixz="0" iyy="2.6041666666666672e-05" iyz="0" izz="0.0018880208333333333"/>
    </inertial>
  </link>
  <joint name="lidar_stand_joint" type="fixed">
    <parent link="base_link"/>
    <child link="lidar_stand"/>
    <origin xyz=".2 0 0.15"/>
  </joint>
  <link name="imu_link">
    <pose frame="">0 0 0 0 -0 0</pose>
    <inertial>
      <mass value="0.015"/>
      <inertia ixx="1e-05" ixy="0" ixz="0" iyy="1e-05" iyz="0" izz="1e-05"/>
    </inertial>
    <self_collide>0</self_collide>
    <enable_wind>0</enable_wind>
    <kinematic>0</kinematic>
  </link>
  <joint name="imu_joint" type="fixed">
    <parent link="base_link"/>
    <child link="imu_link"/>
    <pose frame="">0 0 0 0 -0 0</pose>
    <axis>
      <xyz>1 0 0</xyz>
      <use_parent_model_frame>1</use_parent_model_frame>
      <limit>
        <lower>0</lower>
        <upper>0</upper>
        <effort>0</effort>
        <velocity>0</velocity>
      </limit>
      <dynamics>
        <spring_reference>0</spring_reference>
        <spring_stiffness>0</spring_stiffness>
        <damping>0.7</damping>
        <friction>0</friction>
      </dynamics>
    </axis>
    <physics>
      <ode>
        <limit>
          <cfm>0</cfm>
          <erp>0.2</erp>
        </limit>
        <suspension>
          <cfm>0</cfm>
          <erp>0.2</erp>
        </suspension>
      </ode>
    </physics>
  </joint>
  <gazebo reference="imu_link">
    <sensor name="imu_sensor" type="imu">
      <pose frame="">0 0 0 -3.14159 -0 0</pose>
      <always_on>1</always_on>
      <update_rate>1000</update_rate>
      <imu/>
    </sensor>
  </gazebo>
  <link name="left_motor_mount">
    <visual>
      <geometry>
        <box size=".025 .025 0.25"/>
      </geometry>
      <material name="red">
        <color rgba="1 0 0 1"/>
      </material>
    </visual>
    <inertial>
      <mass value=".1"/>
      <inertia ixx="0.0005260416666666667" ixy="0" ixz="0" iyy="1.041666666666667e-05" iyz="0" izz="0.0005260416666666667"/>
    </inertial>
  </link>
  <joint name="left_motor_mount_joint" type="fixed">
    <parent link="base_link"/>
    <child link="left_motor_mount"/>
    <origin xyz="-0.5125 -0.125 -0.15"/>
    <!-- <axis xyz="0 0 1"/>
        <limit lower="${-(deck_height + left_motor_height)/2}" upper="${-(deck_height +
    left_motor_height)/2}" effort="100" velocity="100"/> -->
  </joint>
  <link name="right_motor_mount">
    <visual>
      <geometry>
        <box size=".025 .025 0.25"/>
      </geometry>
      <material name="red">
        <color rgba="1 0 0 1"/>
      </material>
    </visual>
    <inertial>
      <mass value=".1"/>
      <inertia ixx="0.0005260416666666667" ixy="0" ixz="0" iyy="1.041666666666667e-05" iyz="0" izz="0.0005260416666666667"/>
    </inertial>
  </link>
  <joint name="right_motor_mount_joint" type="fixed">
    <parent link="base_link"/>
    <child link="right_motor_mount"/>
    <origin xyz="-0.5125 0.125 -0.15"/>
    <!-- <axis xyz="0 0 1"/>
        <limit lower="0" upper="0" effort="100" velocity="100"/> -->
  </joint>
  <!-- <xacro:propeller side="left"/>  -->
  <link name="left_propeller_link">
    <!-- <pose>0 0 0 0 -1.57079 0</pose> -->
    <inertial>
      <origin rpy="0 1.57 0"/>
      <!-- <pose>0 0 -.16 0 -0 0</pose> -->
      <mass value="0.5"/>
      <inertia ixx="0.008545" ixy="0" ixz="0" iyy="0.008545" iyz="0" izz="0.0144"/>
    </inertial>
    <self_collide>0</self_collide>
    <enable_wind>0</enable_wind>
    <kinematic>0</kinematic>
    <visual name="left_propeller_link_visual">
      <!-- <pose>0 0 0 0 -1.57079 0</pose> -->
      <origin rpy="0 1.57 0"/>
      <geometry>
        <!-- <mesh>
      <scale>1 1 1</scale>
      <uri>model://boat/meshes/propeller.dae</uri>
    </mesh> -->
        <cylinder length="0.09" radius="0.05"/>
      </geometry>
      <material name="red">
        <color rgba="1 0 0 1"/>
      </material>
    </visual>
    <collision name="left_propeller_link_collision">
      <origin rpy="0 1.57 0"/>
      <laser_retro>0</laser_retro>
      <max_contacts>10</max_contacts>
      <!-- <pose>-0.08 0 0 3.14159 -0 3.14159</pose> -->
      <geometry>
        <cylinder length="0.09" radius="0.05"/>
      </geometry>
      <surface>
        <friction>
          <ode>
            <mu>1</mu>
            <mu2>1</mu2>
            <fdir1>0 0 0</fdir1>
            <slip1>0</slip1>
            <slip2>0</slip2>
          </ode>
          <torsional>
            <coefficient>1</coefficient>
            <patch_radius>0</patch_radius>
            <surface_radius>0</surface_radius>
            <use_patch_radius>1</use_patch_radius>
            <ode>
              <slip>0</slip>
            </ode>
          </torsional>
        </friction>
        <bounce>
          <restitution_coefficient>0</restitution_coefficient>
          <threshold>1e+06</threshold>
        </bounce>
        <contact>
          <collide_without_contact>0</collide_without_contact>
          <collide_without_contact_bitmask>1</collide_without_contact_bitmask>
          <collide_bitmask>1</collide_bitmask>
          <ode>
            <soft_cfm>0</soft_cfm>
            <soft_erp>0.2</soft_erp>
            <kp>1e+13</kp>
            <kd>1</kd>
            <max_vel>0.01</max_vel>
            <min_depth>0</min_depth>
          </ode>
          <bullet>
            <split_impulse>1</split_impulse>
            <split_impulse_penetration_threshold>-0.01</split_impulse_penetration_threshold>
            <soft_cfm>0</soft_cfm>
            <soft_erp>0.2</soft_erp>
            <kp>1e+13</kp>
            <kd>1</kd>
          </bullet>
        </contact>
      </surface>
    </collision>
  </link>
  <gazebo reference="left_propeller_link">
    <pose relative_to="left_motor_joint">0 0 0 0 -0 0</pose>
  </gazebo>
  <joint name="left_motor_joint" type="revolute">
    <parent link="base_link"/>
    <child link="left_propeller_link"/>
    <origin xyz="-0.5  0.125 -0.25"/>
    <limit effort="-1" lower="-1e+16" upper="1e+16" velocity="-1"/>
    <axis xyz="1 0 0"/>
    <physics>
      <ode>
        <limit>
          <cfm>0</cfm>
          <erp>0.2</erp>
        </limit>
        <suspension>
          <cfm>0</cfm>
          <erp>0.2</erp>
        </suspension>
      </ode>
    </physics>
  </joint>
  <gazebo reference="left_motor_joint">
    <use_parent_model_frame>1</use_parent_model_frame>
  </gazebo>
  <link name="right_propeller_link">
    <!-- <pose>0 0 0 0 -1.57079 0</pose> -->
    <inertial>
      <!-- <pose>0 0 -.16 0 -0 0</pose> -->
      <origin rpy="0 1.57 0"/>
      <mass value="0.5"/>
      <inertia ixx="0.008545" ixy="0" ixz="0" iyy="0.008545" iyz="0" izz="0.0144"/>
    </inertial>
    <self_collide>0</self_collide>
    <enable_wind>0</enable_wind>
    <kinematic>0</kinematic>
    <visual name="right_propeller_link_visual">
      <!-- <pose>0 0 0 0 -1.57079 0</pose> -->
      <geometry>
        <!-- <mesh>
    <scale>1 1 1</scale>
    <uri>model://boat/meshes/propeller.dae</uri>
  </mesh> -->
        <cylinder length="0.09" radius="0.05"/>
      </geometry>
      <origin rpy="0 1.57 0"/>
      <material name="red">
        <color rgba="1 0 0 1"/>
      </material>
    </visual>
    <collision name="right_propeller_link_collision">
      <origin rpy="0 1.57 0"/>
      <laser_retro>0</laser_retro>
      <max_contacts>10</max_contacts>
      <!-- <pose>-0.08 0 0 3.14159 -0 3.14159</pose> -->
      <geometry>
        <cylinder length="0.09" radius="0.05"/>
      </geometry>
      <surface>
        <friction>
          <ode>
            <mu>1</mu>
            <mu2>1</mu2>
            <fdir1>0 0 0</fdir1>
            <slip1>0</slip1>
            <slip2>0</slip2>
          </ode>
          <torsional>
            <coefficient>1</coefficient>
            <patch_radius>0</patch_radius>
            <surface_radius>0</surface_radius>
            <use_patch_radius>1</use_patch_radius>
            <ode>
              <slip>0</slip>
            </ode>
          </torsional>
        </friction>
        <bounce>
          <restitution_coefficient>0</restitution_coefficient>
          <threshold>1e+06</threshold>
        </bounce>
        <contact>
          <collide_without_contact>0</collide_without_contact>
          <collide_without_contact_bitmask>1</collide_without_contact_bitmask>
          <collide_bitmask>1</collide_bitmask>
          <ode>
            <soft_cfm>0</soft_cfm>
            <soft_erp>0.2</soft_erp>
            <kp>1e+13</kp>
            <kd>1</kd>
            <max_vel>0.01</max_vel>
            <min_depth>0</min_depth>
          </ode>
          <bullet>
            <split_impulse>1</split_impulse>
            <split_impulse_penetration_threshold>-0.01</split_impulse_penetration_threshold>
            <soft_cfm>0</soft_cfm>
            <soft_erp>0.2</soft_erp>
            <kp>1e+13</kp>
            <kd>1</kd>
          </bullet>
        </contact>
      </surface>
    </collision>
  </link>
  <joint name="right_motor_joint" type="revolute">
    <parent link="base_link"/>
    <child link="right_propeller_link"/>
    <origin xyz="-0.5 -0.125 -0.25"/>
    <limit effort="-1" lower="-1e+16" upper="1e+16" velocity="-1"/>
    <axis xyz="1 0 0"/>
    <physics>
      <ode>
        <limit>
          <cfm>0</cfm>
          <erp>0.2</erp>
        </limit>
        <suspension>
          <cfm>0</cfm>
          <erp>0.2</erp>
        </suspension>
      </ode>
    </physics>
  </joint>
  <gazebo reference="right_motor_joint">
    <use_parent_model_frame>1</use_parent_model_frame>
  </gazebo>

</robot>

