<sdf version='1.7'>
  <model name='athena'>
    <link name='dummy_base_link'>
      <inertial>
        <pose>-0.026316 -0 0.022556 0 -0 0</pose>
        <mass>0.665</mass>
        <inertia>
          <ixx>0.0248904</ixx>
          <ixy>-8.21711e-19</ixy>
          <ixz>-0.0258947</ixz>
          <iyy>0.0952241</iyy>
          <iyz>-3.91291e-20</iyz>
          <izz>0.0825573</izz>
        </inertia>
      </inertial>
      <collision name='dummy_base_link_fixed_joint_lump__base_link_collision'>
        <pose>0 0 0 0 -0 0</pose>
        <geometry>
          <box>
            <size>1 0.5 0.05</size>
          </box>
        </geometry>
      </collision>
      <collision name='dummy_base_link_fixed_joint_lump__left_hull_collision_1'>
        <pose>0 -0.25 -0.125 0 1.5708 0</pose>
        <geometry>
          <cylinder>
            <length>1</length>
            <radius>0.1</radius>
          </cylinder>
        </geometry>
      </collision>
      <collision name='dummy_base_link_fixed_joint_lump__right_hull_collision_2'>
        <pose>0 0.25 -0.125 0 1.5708 0</pose>
        <geometry>
          <cylinder>
            <length>1</length>
            <radius>0.1</radius>
          </cylinder>
        </geometry>
      </collision>
      <visual name='dummy_base_link_fixed_joint_lump__base_link_visual'>
        <pose>0 0 0 0 -0 0</pose>
        <geometry>
          <box>
            <size>1 0.5 0.05</size>
          </box>
        </geometry>
      </visual>
      <visual name='dummy_base_link_fixed_joint_lump__camera_stand_visual_1'>
        <pose>0.35 0 0.05 0 -0 0</pose>
        <geometry>
          <box>
            <size>0.025 0.025 0.1</size>
          </box>
        </geometry>
      </visual>
      <visual name='dummy_base_link_fixed_joint_lump__camera_link_visual_2'>
        <pose>0.35 0 0.1 0 -0 0</pose>
        <geometry>
          <box>
            <size>0.025 0.05 0.025</size>
          </box>
        </geometry>
      </visual>
      <visual name='dummy_base_link_fixed_joint_lump__left_hull_visual_3'>
        <pose>0 -0.25 -0.125 0 1.5708 0</pose>
        <geometry>
          <cylinder>
            <length>1</length>
            <radius>0.1</radius>
          </cylinder>
        </geometry>
      </visual>
      <visual name='dummy_base_link_fixed_joint_lump__left_motor_mount_visual_4'>
        <pose>-0.5125 -0.125 -0.15 0 -0 0</pose>
        <geometry>
          <box>
            <size>0.025 0.025 0.25</size>
          </box>
        </geometry>
      </visual>
      <visual name='dummy_base_link_fixed_joint_lump__lidar_stand_visual_5'>
        <pose>0.2 0 0.15 0 -0 0</pose>
        <geometry>
          <box>
            <size>0.025 0.025 0.3</size>
          </box>
        </geometry>
      </visual>
      <visual name='dummy_base_link_fixed_joint_lump__right_hull_visual_6'>
        <pose>0 0.25 -0.125 0 1.5708 0</pose>
        <geometry>
          <cylinder>
            <length>1</length>
            <radius>0.1</radius>
          </cylinder>
        </geometry>
      </visual>
      <visual name='dummy_base_link_fixed_joint_lump__right_motor_mount_visual_7'>
        <pose>-0.5125 0.125 -0.15 0 -0 0</pose>
        <geometry>
          <box>
            <size>0.025 0.025 0.25</size>
          </box>
        </geometry>
      </visual>
      <sensor name='camera1' type='camera'>
        <always_on>1</always_on>
        <update_rate>30</update_rate>
        <plugin name='camera_controller' filename='libgazebo_ros_camera.so'>
          <alwaysOn>1</alwaysOn>
          <updateRate>0.0</updateRate>
          <cameraName>zed2i</cameraName>
          <imageTopicName>/zed2i/zed_node/rgb/image_rect_color</imageTopicName>
          <cameraInfoTopicName>/zed_node/camera_info</cameraInfoTopicName>
          <frameName>camera_link</frameName>
          <hackBaseline>0.07</hackBaseline>
          <distortionK1>0.0</distortionK1>
          <distortionK2>0.0</distortionK2>
          <distortionK3>0.0</distortionK3>
          <distortionT1>0.0</distortionT1>
          <distortionT2>0.0</distortionT2>
        </plugin>
        <pose>0.35 0 0.1 0 -0 0</pose>
        <horizontal_fov>1.047</horizontal_fov>
        <image>
          <width>640</width>
          <height>480</height>
        </image>
        <clip>
          <near>0.1</near>
          <far>100</far>
        </clip>
      </sensor>
      <sensor name='imu_sensor' type='imu'>
        <always_on>1</always_on>
        <update_rate>1000</update_rate>
        <imu/>
        <pose>0 0 0 0 -0 0</pose>
      </sensor>
    </link>
    <joint name='left_motor_joint' type='revolute'>
      <pose relative_to='dummy_base_link'>-0.5 0.125 -0.25 0 -0 0</pose>
      <parent>dummy_base_link</parent>
      <child>left_propeller_link</child>
      <axis>
        <xyz>1 0 0</xyz>
        <limit>
          <lower>-1e+16</lower>
          <upper>1e+16</upper>
          <effort>-1</effort>
          <velocity>-1</velocity>
        </limit>
        <dynamics>
          <spring_reference>0</spring_reference>
          <spring_stiffness>0</spring_stiffness>
        </dynamics>
      </axis>
      <physics>
        <ode>
          <limit>
            <cfm>0</cfm>
            <erp>0.2</erp>
          </limit>
        </ode>
      </physics>
      <use_parent_model_frame>1</use_parent_model_frame>
    </joint>
    <link name='left_propeller_link'>
      <pose relative_to='left_motor_joint'>0 0 0 0 -0 0</pose>
      <inertial>
        <pose>0 0 0 0 1.57 0</pose>
        <mass>0.5</mass>
        <inertia>
          <ixx>0.008545</ixx>
          <ixy>0</ixy>
          <ixz>0</ixz>
          <iyy>0.008545</iyy>
          <iyz>0</iyz>
          <izz>0.0144</izz>
        </inertia>
      </inertial>
      <collision name='left_propeller_link_collision_collision'>
        <pose>0 0 0 0 1.5708 0</pose>
        <geometry>
          <cylinder>
            <length>0.09</length>
            <radius>0.05</radius>
          </cylinder>
        </geometry>
        <surface>
          <contact>
            <ode/>
          </contact>
          <friction>
            <ode/>
          </friction>
        </surface>
      </collision>
      <visual name='left_propeller_link_visual_visual'>
        <pose>0 0 0 0 1.5708 0</pose>
        <geometry>
          <cylinder>
            <length>0.09</length>
            <radius>0.05</radius>
          </cylinder>
        </geometry>
      </visual>
      <pose relative_to='left_motor_joint'>0 0 0 0 -0 0</pose>
    </link>
    <joint name='right_motor_joint' type='revolute'>
      <pose relative_to='dummy_base_link'>-0.5 -0.125 -0.25 0 -0 0</pose>
      <parent>dummy_base_link</parent>
      <child>right_propeller_link</child>
      <axis>
        <xyz>1 0 0</xyz>
        <limit>
          <lower>-1e+16</lower>
          <upper>1e+16</upper>
          <effort>-1</effort>
          <velocity>-1</velocity>
        </limit>
        <dynamics>
          <spring_reference>0</spring_reference>
          <spring_stiffness>0</spring_stiffness>
        </dynamics>
      </axis>
      <physics>
        <ode>
          <limit>
            <cfm>0</cfm>
            <erp>0.2</erp>
          </limit>
        </ode>
      </physics>
      <use_parent_model_frame>1</use_parent_model_frame>
    </joint>
    <link name='right_propeller_link'>
      <pose relative_to='right_motor_joint'>0 0 0 0 -0 0</pose>
      <inertial>
        <pose>0 0 0 0 1.57 0</pose>
        <mass>0.5</mass>
        <inertia>
          <ixx>0.008545</ixx>
          <ixy>0</ixy>
          <ixz>0</ixz>
          <iyy>0.008545</iyy>
          <iyz>0</iyz>
          <izz>0.0144</izz>
        </inertia>
      </inertial>
      <collision name='right_propeller_link_collision_collision'>
        <pose>0 0 0 0 1.5708 0</pose>
        <geometry>
          <cylinder>
            <length>0.09</length>
            <radius>0.05</radius>
          </cylinder>
        </geometry>
      </collision>
      <visual name='right_propeller_link_visual_visual'>
        <pose>0 0 0 0 1.5708 0</pose>
        <geometry>
          <cylinder>
            <length>0.09</length>
            <radius>0.05</radius>
          </cylinder>
        </geometry>
      </visual>
    </link>
    <static>0</static>
    <plugin name='ArduCopter_Plugin' filename='libArduPilotPlugin.so'>
      <fdm_addr>127.0.0.1</fdm_addr>
      <fdm_port_in>9002</fdm_port_in>
      <fdm_port_out>9003</fdm_port_out>
      <modelXYZToAirplaneXForwardZDown>0 0 0 3.141593 0 0</modelXYZToAirplaneXForwardZDown>
      <gazeboXYZToNED>0 0 0 3.141593 0 0</gazeboXYZToNED>
      <imuName>dummy_base_link::imu_sensor</imuName>
      <connectionTimeoutMaxCount>5</connectionTimeoutMaxCount>
      <control channel='0'>
        <type>VELOCITY</type>
        <offset>-0.5</offset>
        <p_gain>1</p_gain>
        <i_gain>0</i_gain>
        <d_gain>0</d_gain>
        <i_max>0</i_max>
        <i_min>0</i_min>
        <cmd_max>10</cmd_max>
        <cmd_min>-10</cmd_min>
        <jointName>left_motor_joint</jointName>
        <multiplier>-100</multiplier>
      </control>
      <control channel='2'>
        <type>VELOCITY</type>
        <offset>-0.5</offset>
        <p_gain>1</p_gain>
        <i_gain>0</i_gain>
        <d_gain>0</d_gain>
        <i_max>0</i_max>
        <i_min>0</i_min>
        <cmd_max>10</cmd_max>
        <cmd_min>-10</cmd_min>
        <jointName>right_motor_joint</jointName>
        <multiplier>-100</multiplier>
      </control>
    </plugin>
    <plugin name='rotor_1_blade_1' filename='libLiftDragPlugin.so'>
      <a0>2</a0>
      <alpha_stall>4</alpha_stall>
      <cla>10.2500</cla>
      <cda>0.10</cda>
      <cma>0.00</cma>
      <cla_stall>-0.025</cla_stall>
      <cda_stall>0.0</cda_stall>
      <cma_stall>0.0</cma_stall>
      <area>0.002</area>
      <air_density>997</air_density>
      <cp>0.084 0 0</cp>
      <forward>0 1 0</forward>
      <upward>0 0 1</upward>
      <link_name>right_propeller_link</link_name>
    </plugin>
    <plugin name='rotor_1_blade_2' filename='libLiftDragPlugin.so'>
      <a0>2</a0>
      <alpha_stall>4</alpha_stall>
      <cla>10.2500</cla>
      <cda>0.10</cda>
      <cma>0.00</cma>
      <cla_stall>-0.025</cla_stall>
      <cda_stall>0.0</cda_stall>
      <cma_stall>0.0</cma_stall>
      <area>0.002</area>
      <air_density>997</air_density>
      <cp>-0.084 0 0</cp>
      <forward>0 -1 0</forward>
      <upward>0 0 1</upward>
      <link_name>left_propeller_link</link_name>
    </plugin>
    <plugin name='usv_dynamics_wamv_dynamics_plugin' filename='libusv_gazebo_dynamics_plugin.so'>
      <waterLevel>.25</waterLevel>
      <waterDensity>997.8</waterDensity>
      <xDotU>0.0</xDotU>
      <yDotV>0.0</yDotV>
      <nDotR>0.0</nDotR>
      <xU>51.3</xU>
      <xUU>72.4</xUU>
      <yV>40.0</yV>
      <yVV>0.0</yVV>
      <zW>500.0</zW>
      <kP>50.0</kP>
      <mQ>50.0</mQ>
      <nR>400.0</nR>
      <nRR>0.0</nRR>
      <hullRadius>0.1</hullRadius>
      <boatWidth>0.7</boatWidth>
      <boatLength>1</boatLength>
      <length_n>2</length_n>
      <wave_n>3</wave_n>
      <wave_amp0>0</wave_amp0>
      <wave_amp1>0</wave_amp1>
      <wave_amp2>0</wave_amp2>
      <wave_period0>12</wave_period0>
      <wave_period1>8</wave_period1>
      <wave_period2>5.33333</wave_period2>
      <wave_direction0>0.921061 -0.389418</wave_direction0>
      <wave_direction1>1 0</wave_direction1>
      <wave_direction2>0.921061 0.389418</wave_direction2>
      <bodyName>dummy_base_link</bodyName>
      <xyzOffset>0 0 0</xyzOffset>
      <rpyOffset>0 -0 0</rpyOffset>
      <ignition::corrected_offsets>1</ignition::corrected_offsets>
    </plugin>
  </model>
</sdf>
